Workbook

Sheet DASHBOARD IRB PD
A1: INDIKATOR PENILAIAN | E1: BOBOT | F1: NILAI | G1: NILAI AKHIR | H1: % | I1: KETERANGAN | J1: EVALUATOR
A2: 1 | E2: 2 | F2: 3 | G2: 4 | H2: 5 | I2: 6 | J2: 7
A3: I. | B3: RB GENERAL PD | E3: =E4+E13+E20 -> 65 | G3: =G4+G13+G20 -> 65 | H3: =G3/E3*100 -> 100
B4: A. | C4: Capaian Sasaran Strategis | E4: =SUM(E5:E12) -> 36 | G4: =SUM(G5:G12) -> 36 | H4: =G4/E4*100 -> 100
C5: 1. | D5: Tingkat Kematangan SPBE Perangkat Daerah | E5: 6 | F5: ='INSTRUMEN INDIKATOR'!K5 -> 100 | G5: =F5*E5% -> 6 | H5: =G5/E5*100 -> 100 | I5: Nilai Kematangan Penerapan SPBE dan Statistik Sektoral pada Perangkat Daerah | J5: Dinas Komunikasi dan Informatika
C6: 2. | D6: Nilai SAKIP Perangkat Daerah | E6: 6 | F6: ='INSTRUMEN INDIKATOR'!K42 -> 100 | G6: =F6*E6% -> 6 | H6: =G6/E6*100 -> 100 | I6: Nilai Evaluasi Akuntabilitas Kinerja Internal | J6: Inspektorat Daerah
C7: 3. | D7: Capaian IKU Perangkat Daerah | E7: 4 | F7: ='INSTRUMEN INDIKATOR'!K48 -> 100 | G7: =F7*E7% -> 4 | H7: =G7/E7*100 -> 100 | I7: Tingkat Ketercapaian Indikator Kinerja Utama Perangkat Daerah sesuai Dokumen Rencana Strategis Perangkat Daerah | J7: Badan Perencanaan Pembangunan Daerah
C8: 4. | D8: Tindaklajut Rekomendasi (TLHP) | E8: 4 | F8: ='INSTRUMEN INDIKATOR'!K51 -> 100 | G8: =F8*E8% -> 4 | H8: =G8/E8*100 -> 100 | I8: Persentase Hasil Tindaklanjut Rekomendasi (TLHP) BPK dan APIP | J8: Inspektorat Daerah
C9: 5. | D9: Laporan Realisasi Anggaran | E9: 4 | F9: ='INSTRUMEN INDIKATOR'!K55 -> 100 | G9: =F9*E9% -> 4 | H9: =G9/E9*100 -> 100 | I9: Persentase Capaian Realisasi APBD tahun sebelumnya dan tahun berjalan | J9: Badan Pengelola Keuangan dan Aset Daerah
C10: 6. | D10: Indeks Budaya Kerja BerAKHLAK | E10: 4 | F10: ='INSTRUMEN INDIKATOR'!K60 -> 100 | G10: =F10*E10% -> 4 | H10: =G10/E10*100 -> 100 | I10: Nilai Hasil Survey Implementasi Kamus Kompetensi ASN BerAKHLAK | J10: Strategic Transformation Unit (STU)
C11: 7. | D11: Nilai Survei Kepuasan Masyarakat | E11: 4 | F11: ='INSTRUMEN INDIKATOR'!K63 -> 100 | G11: =F11*E11% -> 4 | H11: =G11/E11*100 -> 100 | I11: Nilai Hasil Survey Kepuasan Masyarakat pada Aplikasi SKM Terintegrasi | J11: Biro Organisasi Sekretariat Daerah
C12: 8. | D12: Tingkat Keberhasilan Pembangunan ZI | E12: 4 | F12: ='INSTRUMEN INDIKATOR'!K66 -> 100 | G12: =F12*E12% -> 4 | H12: =G12/E12*100 -> 100 | I12: Tingkat Capaian Pelaksanaan Pembangunan Zona Integritas | J12: Inspektorat Daerah
B13: B. | C13: Capaian Pelaksanaan Kebijakan RB | E13: =SUM(E14:E19) -> 24 | G13: =SUM(G14:G19) -> 24 | H13: =G13/E13*100 -> 100
C14: 1. | D14: Indeks Kualitas Pelayanan Publik | E14: 4 | F14: ='INSTRUMEN INDIKATOR'!K70 -> 100 | G14: =F14*E14% -> 4 | H14: =G14/E14*100 -> 100 | I14: Nilai Pengukuran Kualitas Pelayanan Publik Perangkat Daerah | J14: Biro Organisasi Sekretariat Daerah
C15: 2. | D15: Indeks Reformasi Hukum | E15: 4 | F15: ='INSTRUMEN INDIKATOR'!K108 -> 100 | G15: =F15*E15% -> 4 | H15: =G15/E15*100 -> 100 | I15: Nilai Pengukuran Implementasi Reformasi Hukum Perangkat Daerah | J15: Biro Hukum dan HAM Sekretariat Daerah
C16: 3. | D16: Tingkat tindak lanjut pengaduan masyarakat (LAPOR) | E16: 4 | F16: ='INSTRUMEN INDIKATOR'!K119 -> 100 | G16: =F16*E16% -> 4 | H16: =G16/E16*100 -> 100 | I16: Persentase Tindaklanjut Laporan Pengaduan melalui SP4N Lapor | J16: Dinas Komunikasi dan Informatika
C17: 4. | D17: Tingkat Digitalisasi Arsip | E17: 4 | F17: ='INSTRUMEN INDIKATOR'!K128 -> 100 | G17: =F17*E17% -> 4 | H17: =G17/E17*100 -> 100 | I17: Nilai Kualitas Pengelolaan Kearsipan Digital Perangkat Daerah | J17: Dinas Perpustakaan dan Kearsipan
C18: 5. | D18: Indeks Tata Kelola Pengadaan Barang/Jasa Perangkat Daerah | E18: 4 | F18: ='INSTRUMEN INDIKATOR'!K131 -> 100 | G18: =F18*E18% -> 4 | H18: =G18/E18*100 -> 100 | I18: Nilai Kepatuhan Pencatatan Pengadaan Barang/Jasa Pemerintah pada SPSE | J18: Biro Pengadaan Barang dan Jasa Sekretariat Daerah
C19: 6. | D19: Indeks Profesionalitas ASN | E19: 4 | F19: ='INSTRUMEN INDIKATOR'!K139 -> 100 | G19: =F19*E19% -> 4 | H19: =G19/E19*100 -> 100 | I19: Nilai Indeks Profesionalitas ASN Perangkat Daerah | J19: Badan Kepegawaian Daerah dan Badan Pengembangan Sumber Daya Manusia
B20: C. | C20: Capaian Strategis Pelaksanaan RB General | E20: =SUM(E21:E22) -> 5 | G20: =SUM(G21:G22) -> 5 | H20: =G20/E20*100 -> 100
C21: 1. | D21: Rencana Aksi Pembangunan RB General | E21: 2 | F21: ='INSTRUMEN INDIKATOR'!K146 -> 100 | G21: =F21*E21% -> 2 | H21: =G21/E21*100 -> 100 | I21: Dokumen Rencana Aksi Pembangunan RB General telah disusun dan ditetapkan sebagai dokumen formal | J21: Strategic Transformation Unit (STU)
C22: 2. | D22: Tingkat Implementasi Rencana Aksi Pembangunan RB General | E22: 3 | F22: ='INSTRUMEN INDIKATOR'!K149 -> 100 | G22: =F22*E22% -> 3 | H22: =G22/E22*100 -> 100 | I22: Persentase Capaian Rencana Aksi Pembangunan RB General | J22: Strategic Transformation Unit (STU)
A23: II. | B23: RB TEMATIK PERANGKAT DAERAH | E23: =E24+E27 -> 35 | G23: =G24+G27 -> 35 | H23: =G23/E23*100 -> 100
B24: A. | C24: Strategi Membangunan RB Tematik | E24: =SUM(E25:E26) -> 5 | G24: =SUM(G25:G26) -> 5 | H24: =G24/E24*100 -> 100
C25: 1. | D25: Rencana Aksi Pembangunan RB Tematik | E25: 2 | F25: ='INSTRUMEN INDIKATOR'!K154 -> 100 | G25: =F25*E25% -> 2 | H25: =G25/E25*100 -> 100 | I25: Dokumen Rencana Aksi Pembangunan RB Tematik telah disusun dan ditetapkan sebagai dokumen formal memuat logical framework | J25: Strategic Transformation Unit (STU)
C26: 2. | D26: Tingkat Implementasi Rencana Aksi Pembangunan RB Tematik | E26: 3 | F26: ='INSTRUMEN INDIKATOR'!K157 -> 100 | G26: =F26*E26% -> 3 | H26: =G26/E26*100 -> 100 | I26: Persentase Capaian Rencana Aksi Pembangunan RB Tematik | J26: Strategic Transformation Unit (STU)
B27: B. | C27: Capaian Dampak RB Tematik | E27: =SUM(E28:E30) -> 30 | G27: =SUM(G28:G30) -> 30 | H27: =G27/E27*100 -> 100
C28: 1. | D28: Peningkatan Penggunaan Produk Dalam Negeri | E28: 10 | F28: ='INSTRUMEN INDIKATOR'!K161 -> 100 | G28: =F28*E28% -> 10 | H28: =G28/E28*100 -> 100 | I28: Tingkat Realisasi Belanja Pengadaan Barang/Jasa Pemerintah pada setiap perangkat daerah yang menggunakan Produk Dalam Negeri/Tingkat Komponen Dalam Negeri (PDN/TKDN) | J28: Strategic Transformation Unit (STU) dan Tim P3DN
C29: 2. | D29: Digitalisasi Administrasi Pemerintahan | E29: 10 | F29: ='INSTRUMEN INDIKATOR'!K164 -> 100 | G29: =F29*E29% -> 10 | H29: =G29/E29*100 -> 100 | I29: Penyampaian 1 buah "Praktek Baik" Tata Kelola Pemerintahan Berbasis Elektronik (Digital Services) dalam bentuk Media Publikasi seperti majalah elektronik, artikel, jurnal, dll yang dikemas secara informatif dan menarik maksimal 5 halaman | J29: Tim Independen
C30: 3. | D30: Capaian Kinerja Core Business Organisasi | E30: 10 | F30: ='INSTRUMEN INDIKATOR'!K167 -> 100 | G30: =F30*E30% -> 10 | H30: =G30/E30*100 -> 100 | I30: Penyampaian 1 Buah "Praktek Baik" Implementasi RB Tematik (Public Services) dalam bentuk Media Publikasi seperti majalah elektronik, artikel, jurnal, dll yang dikemas secara informatif dan menarik maksimal 5 halaman | J30: Tim Independen
A31: TOTAL NILAI RB PD | E31: =E3+E23 -> 100 | G31: =G3+G23 -> 100 | H31: =G31/E31*100 -> 100

Sheet INSTRUMEN INDIKATOR
A1: Indikator Penilaian | G1: Bobot Nilai | H1: Penjelasan/Parameter/Instrumen Evaluasi | I1: Pilihan Jawaban | J1: Jawaban | K1: Nilai | L1: Bukti Dukung | M1: Penanggungjawab Evaluasi
A2: 1 | G2: 2 | H2: 3 | I2: 4 | J2: 5 | K2: 6 | L2: 7 | M2: 8
A3: I. | B3: RB GENERAL PD | G3: =AVERAGE(G4,G69,G145) -> 100 | K3: =AVERAGE(K4,K69,K145) -> 100
B4: A. | C4: Capaian Sasaran Strategis | G4: =AVERAGE(G5,G42,G48,G51,G55,G60,G63,G66) -> 100 | K4: =AVERAGE(K5,K42,K48,K51,K55,K60,K63,K66) -> 100
C5: 1. | D5: Tingkat Kematangan SPBE Perangkat Daerah | G5: =G6+G22+G37 -> 100 | H5: Nilai Kematangan Penerapan SPBE Perangkat Daerah | K5: =K6+K22+K37 -> 100
D6: 1.1 | E6: Tingkat Kematangan Kapabilitas Proses | G6: 50 | K6: =AVERAGE(K7:K21)*G6% -> 50
E7: a) | F7: Telah Memiliki Dokumen Arsitektur SPBE Perangkat Daerah | H7: A. Sudah Menyusun Arsitektur SPBE Domain Proses Bisnis, Layanan, Data dan Informasi, dan Aplikasi B. Sudah Menyusun Arsitektur SPBE Domain Proses Bisnis, Layanan dan Data dan Informasi C. Sudah Menyusun Arsitektur SPBE Domain Proses Bisnis dan Layanan D. Sudah Menyusun Arsitektur SPBE Domain Proses Bisnis | I7: A/B/C/D | J7: A | K7: =IF(I7="A/B/C/D",IF(J7="A",100,IF(J7="B",65,IF(J7="C",35,IF(J7="D",0,"Blm Diisi"))))) -> 100 | L7: Template excel versi Kemanpanrb 1. Domain Proses Bisnis (sampai level n dan kelengkapan metadata) 2. Domain Layanan (selaras dengan Standar Pelayanan Minimal/SPM dan/atau Standar Pelayanan/SP) 3. Domain Aplikasi (selaras dengan Layanan dan data/informasi-nya) 4. Domain Data dan Informasi (selaras dengan Aplikasi layanan, Aplikasi Satu Data/Satu Peta, dan Sistem Penghubung Layanan/SPL ataupun API) 5. Domain Infrastruktur (optional/wajib bagi yang memiliki infrastruktur sendiri dan memanfaatkan Pusat Data Nasional) 6. Domain Keamanan Informasi (optional/wajib bagi yang telah menerapkan Sistem Manajemen Keamanan Informasi/ISO 27001) | M7: Dinas Komunikasi & Informatika
E8: b) | F8: Telah Memiliki Dokumen Peta Rencana (Roadmap) Penerapan SPBE Perangkat Daerah | H8: Terdapat dokumen peta rencana (roadmap) SPBE | I8: Ya/Tidak | J8: Ya | K8: =IF(I8="Ya/Tidak",IF(J8="Ya",100,IF(J8="Tidak",0,"Blm Diisi"))) -> 100 | L8: Roadmap TIK yang dimiliki PD (Dokumen peta jalan TIK/Rencana Induk TIK/Masterplan Pengembangan TIK) dan Renstra PD | M8: Dinas Komunikasi & Informatika
E9: c) | F9: Telah mengalokasikan anggaran pelaksanaan SPBE setiap tahunnya | H9: A. Tindak lanjut hasil evaluasi Anggaran SPBE dalam bentuk RKA/ DPA TA berikutnya B. Terdapat dokumentasi hasil reviu dan evaluasi Anggaran SPBE C. Rencana dan Anggaran SPBE dikonsultasikan ke Diskominfo D. Terdapat Alokasi anggaran pelaksanaan SPBE setiap tahunnya pada Dokumen Pelaksanaan Anggaran | I9: A/B/C/D | J9: A | K9: =IF(I9="A/B/C/D",IF(J9="A",100,IF(J9="B",65,IF(J9="C",35,IF(J9="D",0,"Blm Diisi"))))) -> 100 | L9: Alokasi anggaran TIK diselaraskan antara roadmap dengan renstra | M9: Dinas Komunikasi & Informatika
E10: d) | F10: Telah melaksanakan Inovasi Peta Proses Bisnis | H10: A. Tindak Lanjut Evaluasi Proses Bisnis diterapkan kembali ke Sistem Elektronik Versi Berikutnya B. Reviu dan Evaluasi Proses Bisnis yang sudah diterapkan ke dalam Sistem Elektronik C. Terdapat Proses Bisnis yang sudah diterapkan ke dalam Sistem Elektronik D. Sudah Memiliki Peta Proses Bisnis | I10: A/B/C/D | J10: A | K10: =IF(I10="A/B/C/D",IF(J10="A",100,IF(J10="B",65,IF(J10="C",35,IF(J10="D",0,"Blm Diisi"))))) -> 100 | L10: Identifikasi inovasi berbasis TIK baru yang berbeda dengan proses bisnis sebelumnya | M10: Dinas Komunikasi & Informatika
E11: e) | F11: Telah menerapkan proses pembangunan Aplikasi SPBE sesuai siklus pembangunan aplikasi | H11: A. Proses pembangunan/ pengembangan aplikasi telah direviu dan dievaluasi serta ditindaklanjuti B. Perangkat Daerah melakukan Pembangunan/Pengembangan Aplikasi sesuai Rekomendasi Kementerian PAN RB C. Dokumentasi Proses Pembangunan/Pengembangan Aplikasi sesuai Siklus Pembangunan Aplikasi / SDLC secara lengkap. D. Perangkat Daerah konsultasi dengan Diskominfo dalam proses Pembangunan/ Pengembangan Aplikasi | I11: A/B/C/D | J11: A | K11: =IF(I11="A/B/C/D",IF(J11="A",100,IF(J11="B",65,IF(J11="C",35,IF(J11="D",0,"Blm Diisi"))))) -> 100 | L11: Sesuai dengan standar teknis pembangunan/pengembangan aplikasi di lingkungan Pemerintah Provinsi Sulawesi Tengah (Koordinasi dengan bidang aptika diskominfo) | M11: Dinas Komunikasi & Informatika
E12: f) | F12: Telah memanfaatkan Layanan Pusat Data Pemerintah Daerah | H12: Terdapat aktivitas penggunaan Layanan Pusat Data Pemerintah Daerah | I12: Ya/Tidak | J12: Ya | K12: =IF(I12="Ya/Tidak",IF(J12="Ya",100,IF(J12="Tidak",0,"Blm Diisi"))) -> 100 | L12: Nota Dinas, Surat Permohonan, Surat Balasan, dan Berita Acara Pemanfaatan Pusat Data Pemerintah Daerah | M12: Dinas Komunikasi & Informatika
E13: g) | F13: Telah menggunakan Layanan Jaringan Intra Pemerintah Daerah | H13: Terdapat aktivitas penggunaan Layanan Jaringan Intra Pemerintah Daerah | I13: Ya/Tidak | J13: Ya | K13: =IF(I13="Ya/Tidak",IF(J13="Ya",100,IF(J13="Tidak",0,"Blm Diisi"))) -> 100 | L13: Nota Dinas, Surat Permohonan, Surat Balasan, dan Berita Acara Pemanfaatan Jaringan Intra Pemerintah Daerah, Laporan Pemanfaatan | M13: Dinas Komunikasi & Informatika
E14: h) | F14: Telah menggunakan Sistem Penghubung Layanan Pemerintah Daerah | H14: Terdapat aktivitas penggunaan Sistem Penghubung Layanan Pemerintah Daerah | I14: Ya/Tidak | J14: Ya | K14: =IF(I14="Ya/Tidak",IF(J14="Ya",100,IF(J14="Tidak",0,"Blm Diisi"))) -> 100 | L14: Surat Edaran, Surat Permohonan, Surat Balasan, dan Berita Acara Pemanfaatan Sistem Penghubung Layanan Pemerintah Daerah | M14: Dinas Komunikasi & Informatika
E15: i) | F15: Telah terdapat Tim Pelaksana SPBE Perangkat Daerah | H15: Terdapat Tim Pelaksana SPBE Perangkat Daerah yang salah satu fungsinya adalah melakukan koordinasi dengan Instansi Penganggungjawab SPBE terkait penerapan SPBE di Perangkat Daerah/Unit Kerja | I15: Ya/Tidak | J15: Ya | K15: =IF(I15="Ya/Tidak",IF(J15="Ya",100,IF(J15="Tidak",0,"Blm Diisi"))) -> 100 | L15: Surat Perintah Tim Pengelola TIK/SPBE/Tim Layanan Digital | M15: Dinas Komunikasi & Informatika
E16: j) | F16: Telah menerapkan Manajemen Risiko SPBE | H16: Terdapat Dokumen Manajemen Risiko SPBE | I16: Ya/Tidak | J16: Ya | K16: =IF(I16="Ya/Tidak",IF(J16="Ya",100,IF(J16="Tidak",0,"Blm Diisi"))) -> 100 | L16: Dokumen Manajemen Risiko SPBE PD | M16: Dinas Komunikasi & Informatika
E17: k) | F17: Telah melakukan self-assessment Indeks KAMI | H17: Terdapat Dokumen/Laporan Self-Assessment Indeks KAMI | I17: Ya/Tidak | J17: Ya | K17: =IF(I17="Ya/Tidak",IF(J17="Ya",100,IF(J17="Tidak",0,"Blm Diisi"))) -> 100 | L17: Laporan pelaksanaan Indeks KAMI (Diskominfo), Dashboard Indeks KAMI (PD lain) | M17: Dinas Komunikasi & Informatika
E18: l) | F18: Telah menerapkan Tanda Tangan Elektronik pada Naskah Dokumen Elektronik | H18: Terdapat Laporan Rekapitulasi Pemanfaatan Penggunaan Tanda Tangan Elektronik | I18: Ya/Tidak | J18: Ya | K18: =IF(I18="Ya/Tidak",IF(J18="Ya",100,IF(J18="Tidak",0,"Blm Diisi"))) -> 100 | L18: Laporan Rekapitulasi Pemanfaatan Penggunaan Tanda Tangan Elektronik | M18: Dinas Komunikasi & Informatika
E19: m) | F19: Telah melaksanakan Manajemen Data | H19: Terdapat Dokumen Manajemen Data (mencakup pengelolaan arsitektur data (bid. statistik), data induk, data referensi (tiap PD berbeda, mengacu ke pusat), basis data, kualitas data (data ada di JDS), dan interoperabilitas data) | I19: Ya/Tidak | J19: Ya | K19: =IF(I19="Ya/Tidak",IF(J19="Ya",100,IF(J19="Tidak",0,"Blm Diisi"))) -> 100 | L19: Dokumen Manajemen Data PD (List user, log aktivitas, dataset PD) | M19: Dinas Komunikasi & Informatika
E20: n) | F20: Telah menerapkan Manajemen Aset TIK | H20: Terdapat Dokumen/Laporan Manajemen Aset TIK | I20: Ya/Tidak | J20: Ya | K20: =IF(I20="Ya/Tidak",IF(J20="Ya",100,IF(J20="Tidak",0,"Blm Diisi"))) -> 100 | L20: Dokumen Manajemen Aset TIK PD | M20: Dinas Komunikasi & Informatika
E21: o) | F21: Telah dilakukan pemenuhan kompetensi Sumber Daya Manusia TIK | H21: Terdapat Dokumen/Laporan Pemenuhan Kompetensi Sumber Daya Manusia TIK | I21: Ya/Tidak | J21: Ya | K21: =IF(I21="Ya/Tidak",IF(J21="Ya",100,IF(J21="Tidak",0,"Blm Diisi"))) -> 100 | L21: Dokumen Okupasi Pemetaan Kompetensi SDM TIK PD | M21: Dinas Komunikasi & Informatika
D22: 1.2 | E22: Tingkat Kematangan Kapabilitas Layanan | G22: 30 | K22: =AVERAGE(K23:K36)*G22% -> 30
E23: a) | F23: Telah Menggunakan Layanan Perencanan Berbasis Elektronik | H23: Telah menggunakan Sistem Informasi Pembangunan Daerah (SIPD) dimensi perencanaan | I23: Ya/Tidak | J23: Ya | K23: =IF(I23="Ya/Tidak",IF(J23="Ya",100,IF(J23="Tidak",0,"Blm Diisi"))) -> 100 | L23: Screenshot Pemanfaatan SIPD (Perencanaan) | M23: Dinas Komunikasi & Informatika
E24: b) | F24: Telah Menggunakan Layanan Penganggaran Berbasis Elektronik | H24: Telah menggunakan Sistem Informasi Pembangunan Daerah (SIPD) dimensi penganggaran | I24: Ya/Tidak | J24: Ya | K24: =IF(I24="Ya/Tidak",IF(J24="Ya",100,IF(J24="Tidak",0,"Blm Diisi"))) -> 100 | L24: Screenshot Pemanfaatan SIPD (Penganggaran) | M24: Dinas Komunikasi & Informatika
E25: c) | F25: Telah Menggunakan Layanan Keuangan Berbasis Elektronik | H25: Telah menggunakan Sistem Informasi Penatausahaan Keuangan Daerah (SIKD) | I25: Ya/Tidak | J25: Ya | K25: =IF(I25="Ya/Tidak",IF(J25="Ya",100,IF(J25="Tidak",0,"Blm Diisi"))) -> 100 | L25: Screenshot Pemanfaatan SIPD (Penatausahaan Keuangan Daerah) | M25: Dinas Komunikasi & Informatika
E26: d) | F26: Telah Menggunakan Layanan Pengadaan Barang/Jasa Berbasis Elektronik | H26: Telah mengunakan Sistem Pengadaan Secara Elektronik (SPSE) | I26: Ya/Tidak | J26: Ya | K26: =IF(I26="Ya/Tidak",IF(J26="Ya",100,IF(J26="Tidak",0,"Blm Diisi"))) -> 100 | L26: Screenshot Pemanfaatan SPSE | M26: Dinas Komunikasi & Informatika
E27: e) | F27: Telah Menggunakan Layanan Kepegawaian Berbasis Elektronik | H27: Telah menggunakan SIAP Sulteng | I27: Ya/Tidak | J27: Ya | K27: =IF(I27="Ya/Tidak",IF(J27="Ya",100,IF(J27="Tidak",0,"Blm Diisi"))) -> 100 | L27: Screenshot Pemanfaatan SIAP Sulteng dan menu-menu layanan kepegawaian di dalam SIAP Sulteng (untuk PD lain) | M27: Dinas Komunikasi & Informatika
E28: f) | F28: Telah Menggunakan Layanan Kearsipan Dinamis Berbasis Elektronik | H28: Telah menggunakan SRIKANDI | I28: Ya/Tidak | J28: Ya | K28: =IF(I28="Ya/Tidak",IF(J28="Ya",100,IF(J28="Tidak",0,"Blm Diisi"))) -> 100 | L28: Screenshot Pemanfaatan SRIKANDI | M28: Dinas Komunikasi & Informatika
E29: g) | F29: Telah Menggunakan Layanan Pengelolaan Barang Milik Daerah Berbasis Elektronik | H29: Telah menggunakan aplikasi terkait Aset (BMD) | I29: Ya/Tidak | J29: Ya | K29: =IF(I29="Ya/Tidak",IF(J29="Ya",100,IF(J29="Tidak",0,"Blm Diisi"))) -> 100 | L29: Screenshot Pemanfaatan Aplikasi Aset | M29: Dinas Komunikasi & Informatika
E30: h) | F30: Telah Menggunakan Layanan Pengawasan Internal Pemerintah Berbasis Elektronik | H30: Telah menggunakan Sistem Pengawasan Internal Pemerintah (SPIP) | I30: Ya/Tidak | J30: Ya | K30: =IF(I30="Ya/Tidak",IF(J30="Ya",100,IF(J30="Tidak",0,"Blm Diisi"))) -> 100 | L30: Screenshot Pemanfaatan Aplikasi SPIP | M30: Dinas Komunikasi & Informatika
E31: i) | F31: Telah Menggunakan Layanan Akuntabilitas Kinerja Organisasi Berbasis Elektronik | H31: Telah menggunakan (e-SAKIP) | I31: Ya/Tidak | J31: Ya | K31: =IF(I31="Ya/Tidak",IF(J31="Ya",100,IF(J31="Tidak",0,"Blm Diisi"))) -> 100 | L31: Screenshot Pemanfaatan Aplikasi Sistem AKIP (Biro Organisasi dan Kemenpanrb) | M31: Dinas Komunikasi & Informatika
E32: j) | F32: Telah Menggunakan Layanan Kinerja Pegawai Berbasis Elektronik | H32: Telah menggunakan eKinerja | I32: Ya/Tidak | J32: Ya | K32: =IF(I32="Ya/Tidak",IF(J32="Ya",100,IF(J32="Tidak",0,"Blm Diisi"))) -> 100 | L32: Screenshot Pemanfaatan eKinerja | M32: Dinas Komunikasi & Informatika
E33: k) | F33: Telah Menggunakan Layanan Pengaduan Pelayanan Publik Berbasis Elektronik | H33: Telah menggunakan SP4N-LAPOR | I33: Ya/Tidak | J33: Ya | K33: =IF(I33="Ya/Tidak",IF(J33="Ya",100,IF(J33="Tidak",0,"Blm Diisi"))) -> 100 | L33: Rekap pengelolaan pengaduan | M33: Dinas Komunikasi & Informatika
E34: l) | F34: Telah menggunakan Layanan Data Terbuka Berbasis Elektronik | H34: Telah menggunakan aplikasi Open Data | I34: Ya/Tidak | J34: Ya | K34: =IF(I34="Ya/Tidak",IF(J34="Ya",100,IF(J34="Tidak",0,"Blm Diisi"))) -> 100 | L34: Respon PD terkait Form Permintaan Data | M34: Dinas Komunikasi & Informatika
... E36: n) | F36: Telah Memiliki Layanan Berbasis Elektronik | H36: Telah memiliki layanan berbasis elektronik sesuai dengan core bisnis Perangkat Daerah | I36: Ya/Tidak | J36: Ya | K36: =IF(I36="Ya/Tidak",IF(J36="Ya",100,IF(J36="Tidak",0,"Blm Diisi"))) -> 100 | L36: Dokumentasi pengembangan layanan berbasis elektronik (sesuai siklus SDLC, manualbook, vidio penggunaan) | M36: Dinas Komunikasi & Informatika
D37: 1.3 | E37: Penyelenggaraan Statistik Sektoral | G37: 20 | K37: =AVERAGE(K38:K41)*G37% -> 20
E38: a) | F38: Telah Memiliki Standar Data Statistik | H38: Telah memiliki standar data statistik yang lengkap untuk semua Indikator Kinerja Utama (IKU) yang diampu dinas Rumus: (Jumlah IKU yang memiliki standar data dibagi jumlah total IKU) * 100% | I38: 0-100 | J38: 100 | K38: =J38 -> 100 | L38: Dokumen standar data IKU Perangkat Daerah yang sesuai dengan Peraturan BPS no. 4 Tahun 2021 tentang SDSN | M38: Dinas Komunikasi & Informatika
E39: b) | F39: Persentase Data yang Memiliki Metadata | H39: Tersedianya metadata terstandar (sesuai Perka BPS No. 5 Tahun 2020) untuk semua IKU Rumus: (Jumlah metadata IKU yang tersedia dibagi jumlah total IKU) * 100% | I39: 0-100 | J39: 100 | K39: =J39 -> 100 | L39: Dokumen metadata IKU Perangkat Daerah sesuai dengan Peraturan BPS no. 5 Tahun 2020 tentang Petunjuk Teknis Metadata Statistik | M39: Dinas Komunikasi & Informatika
E40: c) | F40: Persentase Keterisian Data Prioritas (Relevansi) | H40: Persentase keterisian data prioritas Rumus: (Jumlah data prioritas yang tersedia di Satu Data dibagi Potensi data prioritas) * 100% | I40: 0-100 | J40: 100 | K40: =J40 -> 100 | L40: List data prioritas dari masing-masing Perangkat Daerah (dari Bappeda) | M40: Dinas Komunikasi & Informatika
E41: d) | F41: Persentase Data yang Dirilis sesuai Jadwal (Aktualisasi & Ketepatan Waktu) | H41: Persentase data prioritas yang terupdate sesuai waktu A = 100% terupdate B = 75% terupdate C = 50% terupdate D = 25% terupdate E = belum terupdate (0%) | I41: A/B/C/D/E | J41: A | K41: =IF(J41="E",0,IF(J41="D",25,IF(J41="C",50, IF(J41="B",75,100)))) -> 100 | L41: Dokumen jumlah data prioritas yang telah terupdate (per 31 Desember n-1/tahun sebelumnya) pada 30 Juni tahun berjalan | M41: Dinas Komunikasi & Informatika
...

Sheet INDIKATOR EVALUASI SPBE OPD
A1: Indikator Penilaian | G1: Bobot Nilai | H1: Penjelasan/Parameter/Instrumen Evaluasi | I1: Pilihan Jawaban | J1: Jawaban | K1: Nilai | L1: Bukti Dukung | M1: Penanggungjawab Evaluasi
A2: 1 | G2: 2 | H2: 3 | I2: 4 | J2: 5 | K2: 6 | L2: 7 | M2: 8
A3: I. | B3: RB GENERAL PD | G3: =AVERAGE(G4,G69,G145) -> 100 | K3: =AVERAGE(K4,K69,K145) -> 100
B4: A. | C4: Capaian Sasaran Strategis | G4: =AVERAGE(G5,G42,G48,G51,G55,G60,G63,G66) -> 100 | K4: =AVERAGE(K5,K42,K48,K51,K55,K60,K63,K66) -> 100
C5: 1. | D5: Tingkat Kematangan SPBE Perangkat Daerah | G5: =G6+G22+G37 -> 100 | H5: Nilai Kematangan Penerapan SPBE Perangkat Daerah | K5: =K6+K22+K37 -> 100
D6: 1.1 | E6: Tingkat Kematangan Kapabilitas Proses | G6: 50 | K6: =AVERAGE(K7:K21)*G6% -> 50
E7: a) | F7: Telah Memiliki Dokumen Arsitektur SPBE Perangkat Daerah | H7: A. Sudah Menyusun Arsitektur SPBE Domain Proses Bisnis, Layanan, Data dan Informasi, dan Aplikasi B. Sudah Menyusun Arsitektur SPBE Domain Proses Bisnis, Layanan dan Data dan Informasi C. Sudah Menyusun Arsitektur SPBE Domain Proses Bisnis dan Layanan D. Sudah Menyusun Arsitektur SPBE Domain Proses Bisnis | I7: A/B/C/D | J7: A | K7: =IF(I7="A/B/C/D",IF(J7="A",100,IF(J7="B",65,IF(J7="C",35,IF(J7="D",0,"Blm Diisi"))))) -> 100 | L7: Template excel versi Kemanpanrb 1. Domain Proses Bisnis (sampai level n dan kelengkapan metadata) 2. Domain Layanan (selaras dengan Standar Pelayanan Minimal/SPM dan/atau Standar Pelayanan/SP) 3. Domain Aplikasi (selaras dengan Layanan dan data/informasi-nya) 4. Domain Data dan Informasi (selaras dengan Aplikasi layanan, Aplikasi Satu Data/Satu Peta, dan Sistem Penghubung Layanan/SPL ataupun API) 5. Domain Infrastruktur (optional/wajib bagi yang memiliki infrastruktur sendiri dan memanfaatkan Pusat Data Nasional) 6. Domain Keamanan Informasi (optional/wajib bagi yang telah menerapkan Sistem Manajemen Keamanan Informasi/ISO 27001) | M7: Dinas Komunikasi & Informatika
E8: b) | F8: Telah Memiliki Dokumen Peta Rencana (Roadmap) Penerapan SPBE Perangkat Daerah | H8: Terdapat dokumen peta rencana (roadmap) SPBE | I8: Ya/Tidak | J8: Ya | K8: =IF(I8="Ya/Tidak",IF(J8="Ya",100,IF(J8="Tidak",0,"Blm Diisi"))) -> 100 | L8: Roadmap TIK yang dimiliki PD (Dokumen peta jalan TIK/Rencana Induk TIK/Masterplan Pengembangan TIK) dan Renstra PD | M8: Dinas Komunikasi & Informatika
E9: c) | F9: Telah mengalokasikan anggaran pelaksanaan SPBE setiap tahunnya | H9: A. Tindak lanjut hasil evaluasi Anggaran SPBE dalam bentuk RKA/ DPA TA berikutnya B. Terdapat dokumentasi hasil reviu dan evaluasi Anggaran SPBE C. Rencana dan Anggaran SPBE dikonsultasikan ke Diskominfo D. Terdapat Alokasi anggaran pelaksanaan SPBE setiap tahunnya pada Dokumen Pelaksanaan Anggaran | I9: A/B/C/D | J9: A | K9: =IF(I9="A/B/C/D",IF(J9="A",100,IF(J9="B",65,IF(J9="C",35,IF(J9="D",0,"Blm Diisi"))))) -> 100 | L9: Alokasi anggaran TIK diselaraskan antara roadmap dengan renstra | M9: Dinas Komunikasi & Informatika
E10: d) | F10: Telah melaksanakan Inovasi Peta Proses Bisnis | H10: A. Tindak Lanjut Evaluasi Proses Bisnis diterapkan kembali ke Sistem Elektronik Versi Berikutnya B. Reviu dan Evaluasi Proses Bisnis yang sudah diterapkan ke dalam Sistem Elektronik C. Terdapat Proses Bisnis yang sudah diterapkan ke dalam Sistem Elektronik D. Sudah Memiliki Peta Proses Bisnis | I10: A/B/C/D | J10: A | K10: =IF(I10="A/B/C/D",IF(J10="A",100,IF(J10="B",65,IF(J10="C",35,IF(J10="D",0,"Blm Diisi"))))) -> 100 | L10: Identifikasi inovasi berbasis TIK baru yang berbeda dengan proses bisnis sebelumnya | M10: Dinas Komunikasi & Informatika
E11: e) | F11: Telah menerapkan proses pembangunan Aplikasi SPBE sesuai siklus pembangunan aplikasi | H11: A. Proses pembangunan/ pengembangan aplikasi telah direviu dan dievaluasi serta ditindaklanjuti B. Perangkat Daerah melakukan Pembangunan/Pengembangan Aplikasi sesuai Rekomendasi Kementerian PAN RB C. Dokumentasi Proses Pembangunan/Pengembangan Aplikasi sesuai Siklus Pembangunan Aplikasi / SDLC secara lengkap. D. Perangkat Daerah konsultasi dengan Diskominfo dalam proses Pembangunan/ Pengembangan Aplikasi | I11: A/B/C/D | J11: A | K11: =IF(I11="A/B/C/D",IF(J11="A",100,IF(J11="B",65,IF(J11="C",35,IF(J11="D",0,"Blm Diisi"))))) -> 100 | L11: Sesuai dengan standar teknis pembangunan/pengembangan aplikasi di lingkungan Pemerintah Provinsi Sulawesi Tengah (Koordinasi dengan bidang aptika diskominfo) | M11: Dinas Komunikasi & Informatika
E12: f) | F12: Telah memanfaatkan Layanan Pusat Data Pemerintah Daerah | H12: Terdapat aktivitas penggunaan Layanan Pusat Data Pemerintah Daerah | I12: Ya/Tidak | J12: Ya | K12: =IF(I12="Ya/Tidak",IF(J12="Ya",100,IF(J12="Tidak",0,"Blm Diisi"))) -> 100 | L12: Nota Dinas, Surat Permohonan, Surat Balasan, dan Berita Acara Pemanfaatan Pusat Data Pemerintah Daerah | M12: Dinas Komunikasi & Informatika
E13: g) | F13: Telah menggunakan Layanan Jaringan Intra Pemerintah Daerah | H13: Terdapat aktivitas penggunaan Layanan Jaringan Intra Pemerintah Daerah | I13: Ya/Tidak | J13: Ya | K13: =IF(I13="Ya/Tidak",IF(J13="Ya",100,IF(J13="Tidak",0,"Blm Diisi"))) -> 100 | L13: Nota Dinas, Surat Permohonan, Surat Balasan, dan Berita Acara Pemanfaatan Jaringan Intra Pemerintah Daerah, Laporan Pemanfaatan | M13: Dinas Komunikasi & Informatika
E14: h) | F14: Telah menggunakan Sistem Penghubung Layanan Pemerintah Daerah | H14: Terdapat aktivitas penggunaan Sistem Penghubung Layanan Pemerintah Daerah | I14: Ya/Tidak | J14: Ya | K14: =IF(I14="Ya/Tidak",IF(J14="Ya",100,IF(J14="Tidak",0,"Blm Diisi"))) -> 100 | L14: Surat Edaran, Surat Permohonan, Surat Balasan, dan Berita Acara Pemanfaatan Sistem Penghubung Layanan Pemerintah Daerah | M14: Dinas Komunikasi & Informatika
E15: i) | F15: Telah terdapat Tim Pelaksana SPBE Perangkat Daerah | H15: Terdapat Tim Pelaksana SPBE Perangkat Daerah yang salah satu fungsinya adalah melakukan koordinasi dengan Instansi Penganggungjawab SPBE terkait penerapan SPBE di Perangkat Daerah/Unit Kerja | I15: Ya/Tidak | J15: Ya | K15: =IF(I15="Ya/Tidak",IF(J15="Ya",100,IF(J15="Tidak",0,"Blm Diisi"))) -> 100 | L15: Surat Perintah Tim Pengelola TIK/SPBE/Tim Layanan Digital | M15: Dinas Komunikasi & Informatika
E16: j) | F16: Telah menerapkan Manajemen Risiko SPBE | H16: Terdapat Dokumen Manajemen Risiko SPBE | I16: Ya/Tidak | J16: Ya | K16: =IF(I16="Ya/Tidak",IF(J16="Ya",100,IF(J16="Tidak",0,"Blm Diisi"))) -> 100 | L16: Dokumen Manajemen Risiko SPBE PD | M16: Dinas Komunikasi & Informatika
E17: k) | F17: Telah melakukan self-assessment Indeks KAMI | H17: Terdapat Dokumen/Laporan Self-Assessment Indeks KAMI | I17: Ya/Tidak | J17: Ya | K17: =IF(I17="Ya/Tidak",IF(J17="Ya",100,IF(J17="Tidak",0,"Blm Diisi"))) -> 100 | L17: Laporan pelaksanaan Indeks KAMI (Diskominfo), Dashboard Indeks KAMI (PD lain) | M17: Dinas Komunikasi & Informatika
E18: l) | F18: Telah menerapkan Tanda Tangan Elektronik pada Naskah Dokumen Elektronik | H18: Terdapat Laporan Rekapitulasi Pemanfaatan Penggunaan Tanda Tangan Elektronik | I18: Ya/Tidak | J18: Ya | K18: =IF(I18="Ya/Tidak",IF(J18="Ya",100,IF(J18="Tidak",0,"Blm Diisi"))) -> 100 | L18: Laporan Rekapitulasi Pemanfaatan Penggunaan Tanda Tangan Elektronik | M18: Dinas Komunikasi & Informatika
E19: m) | F19: Telah melaksanakan Manajemen Data | H19: Terdapat Dokumen Manajemen Data (mencakup pengelolaan arsitektur data (bid. statistik), data induk, data referensi (tiap PD berbeda, mengacu ke pusat), basis data, kualitas data (data ada di JDS), dan interoperabilitas data) | I19: Ya/Tidak | J19: Ya | K19: =IF(I19="Ya/Tidak",IF(J19="Ya",100,IF(J19="Tidak",0,"Blm Diisi"))) -> 100 | L19: Dokumen Manajemen Data PD (List user, log aktivitas, dataset PD) | M19: Dinas Komunikasi & Informatika
E20: n) | F20: Telah menerapkan Manajemen Aset TIK | H20: Terdapat Dokumen/Laporan Manajemen Aset TIK | I20: Ya/Tidak | J20: Ya | K20: =IF(I20="Ya/Tidak",IF(J20="Ya",100,IF(J20="Tidak",0,"Blm Diisi"))) -> 100 | L20: Dokumen Manajemen Aset TIK PD | M20: Dinas Komunikasi & Informatika
E21: o) | F21: Telah dilakukan pemenuhan kompetensi Sumber Daya Manusia TIK | H21: Terdapat Dokumen/Laporan Pemenuhan Kompetensi Sumber Daya Manusia TIK | I21: Ya/Tidak | J21: Ya | K21: =IF(I21="Ya/Tidak",IF(J21="Ya",100,IF(J21="Tidak",0,"Blm Diisi"))) -> 100 | L21: Dokumen Okupasi Pemetaan Kompetensi SDM TIK PD | M21: Dinas Komunikasi & Informatika
D22: 1.2 | E22: Tingkat Kematangan Kapabilitas Layanan | G22: 30 | K22: =AVERAGE(K23:K36)*G22% -> 30
E23: a) | F23: Telah Menggunakan Layanan Perencanan Berbasis Elektronik | H23: Telah menggunakan Sistem Informasi Pembangunan Daerah (SIPD) dimensi perencanaan | I23: Ya/Tidak | J23: Ya | K23: =IF(I23="Ya/Tidak",IF(J23="Ya",100,IF(J23="Tidak",0,"Blm Diisi"))) -> 100 | L23: Screenshot Pemanfaatan SIPD (Perencanaan) | M23: Dinas Komunikasi & Informatika
E24: b) | F24: Telah Menggunakan Layanan Penganggaran Berbasis Elektronik | H24: Telah menggunakan Sistem Informasi Pembangunan Daerah (SIPD) dimensi penganggaran | I24: Ya/Tidak | J24: Ya | K24: =IF(I24="Ya/Tidak",IF(J24="Ya",100,IF(J24="Tidak",0,"Blm Diisi"))) -> 100 | L24: Screenshot Pemanfaatan SIPD (Penganggaran) | M24: Dinas Komunikasi & Informatika
E25: c) | F25: Telah Menggunakan Layanan Keuangan Berbasis Elektronik | H25: Telah menggunakan Sistem Informasi Penatausahaan Keuangan Daerah (SIKD) | I25: Ya/Tidak | J25: Ya | K25: =IF(I25="Ya/Tidak",IF(J25="Ya",100,IF(J25="Tidak",0,"Blm Diisi"))) -> 100 | L25: Screenshot Pemanfaatan SIPD (Penatausahaan Keuangan Daerah) | M25: Dinas Komunikasi & Informatika
E26: d) | F26: Telah Menggunakan Layanan Pengadaan Barang/Jasa Berbasis Elektronik | H26: Telah mengunakan Sistem Pengadaan Secara Elektronik (SPSE) | I26: Ya/Tidak | J26: Ya | K26: =IF(I26="Ya/Tidak",IF(J26="Ya",100,IF(J26="Tidak",0,"Blm Diisi"))) -> 100 | L26: Screenshot Pemanfaatan SPSE | M26: Dinas Komunikasi & Informatika
E27: e) | F27: Telah Menggunakan Layanan Kepegawaian Berbasis Elektronik | H27: Telah menggunakan SIAP Sulteng | I27: Ya/Tidak | J27: Ya | K27: =IF(I27="Ya/Tidak",IF(J27="Ya",100,IF(J27="Tidak",0,"Blm Diisi"))) -> 100 | L27: Screenshot Pemanfaatan SIAP Sulteng dan menu-menu layanan kepegawaian di dalam SIAP Sulteng (untuk PD lain) | M27: Dinas Komunikasi & Informatika
E28: f) | F28: Telah Menggunakan Layanan Kearsipan Dinamis Berbasis Elektronik | H28: Telah menggunakan SRIKANDI | I28: Ya/Tidak | J28: Ya | K28: =IF(I28="Ya/Tidak",IF(J28="Ya",100,IF(J28="Tidak",0,"Blm Diisi"))) -> 100 | L28: Screenshot Pemanfaatan SRIKANDI | M28: Dinas Komunikasi & Informatika
E29: g) | F29: Telah Menggunakan Layanan Pengelolaan Barang Milik Daerah Berbasis Elektronik | H29: Telah menggunakan aplikasi terkait Aset (BMD) | I29: Ya/Tidak | J29: Ya | K29: =IF(I29="Ya/Tidak",IF(J29="Ya",100,IF(J29="Tidak",0,"Blm Diisi"))) -> 100 | L29: Screenshot Pemanfaatan Aplikasi Aset | M29: Dinas Komunikasi & Informatika
E30: h) | F30: Telah Menggunakan Layanan Pengawasan Internal Pemerintah Berbasis Elektronik | H30: Telah menggunakan Sistem Pengawasan Internal Pemerintah (SPIP) | I30: Ya/Tidak | J30: Ya | K30: =IF(I30="Ya/Tidak",IF(J30="Ya",100,IF(J30="Tidak",0,"Blm Diisi"))) -> 100 | L30: Screenshot Pemanfaatan Aplikasi SPIP | M30: Dinas Komunikasi & Informatika
E31: i) | F31: Telah Menggunakan Layanan Akuntabilitas Kinerja Organisasi Berbasis Elektronik | H31: Telah menggunakan (e-SAKIP) | I31: Ya/Tidak | J31: Ya | K31: =IF(I31="Ya/Tidak",IF(J31="Ya",100,IF(J31="Tidak",0,"Blm Diisi"))) -> 100 | L31: Screenshot Pemanfaatan Aplikasi Sistem AKIP (Biro Organisasi dan Kemenpanrb) | M31: Dinas Komunikasi & Informatika
E32: j) | F32: Telah Menggunakan Layanan Kinerja Pegawai Berbasis Elektronik | H32: Telah menggunakan eKinerja | I32: Ya/Tidak | J32: Ya | K32: =IF(I32="Ya/Tidak",IF(J32="Ya",100,IF(J32="Tidak",0,"Blm Diisi"))) -> 100 | L32: Screenshot Pemanfaatan eKinerja | M32: Dinas Komunikasi & Informatika
E33: k) | F33: Telah Menggunakan Layanan Pengaduan Pelayanan Publik Berbasis Elektronik | H33: Telah menggunakan SP4N-LAPOR | I33: Ya/Tidak | J33: Ya | K33: =IF(I33="Ya/Tidak",IF(J33="Ya",100,IF(J33="Tidak",0,"Blm Diisi"))) -> 100 | L33: Rekap pengelolaan pengaduan | M33: Dinas Komunikasi & Informatika
E34: l) | F34: Telah menggunakan Layanan Data Terbuka Berbasis Elektronik | H34: Telah menggunakan aplikasi Open Data | I34: Ya/Tidak | J34: Ya | K34: =IF(I34="Ya/Tidak",IF(J34="Ya",100,IF(J34="Tidak",0,"Blm Diisi"))) -> 100 | L34: Respon PD terkait Form Permintaan Data | M34: Dinas Komunikasi & Informatika
... E36: n) | F36: Telah Memiliki Layanan Berbasis Elektronik | H36: Telah memiliki layanan berbasis elektronik sesuai dengan core bisnis Perangkat Daerah | I36: Ya/Tidak | J36: Ya | K36: =IF(I36="Ya/Tidak",IF(J36="Ya",100,IF(J36="Tidak",0,"Blm Diisi"))) -> 100 | L36: Dokumentasi pengembangan layanan berbasis elektronik (sesuai siklus SDLC, manualbook, vidio penggunaan) | M36: Dinas Komunikasi & Informatika
D37: 1.3 | E37: Penyelenggaraan Statistik Sektoral | G37: 20 | K37: =AVERAGE(K38:K41)*G37% -> 20
E38: a) | F38: Telah Memiliki Standar Data Statistik | H38: Telah memiliki standar data statistik yang lengkap untuk semua Indikator Kinerja Utama (IKU) yang diampu dinas Rumus: (Jumlah IKU yang memiliki standar data dibagi jumlah total IKU) * 100% | I38: 0-100 | J38: 100 | K38: =J38 -> 100 | L38: Dokumen standar data IKU Perangkat Daerah yang sesuai dengan Peraturan BPS no. 4 Tahun 2021 tentang SDSN | M38: Dinas Komunikasi & Informatika
E39: b) | F39: Persentase Data yang Memiliki Metadata | H39: Tersedianya metadata terstandar (sesuai Perka BPS No. 5 Tahun 2020) untuk semua IKU Rumus: (Jumlah metadata IKU yang tersedia dibagi jumlah total IKU) * 100% | I39: 0-100 | J39: 100 | K39: =J39 -> 100 | L39: Dokumen metadata IKU Perangkat Daerah sesuai dengan Peraturan BPS no. 5 Tahun 2020 tentang Petunjuk Teknis Metadata Statistik | M39: Dinas Komunikasi & Informatika
E40: c) | F40: Persentase Keterisian Data Prioritas (Relevansi) | H40: Persentase keterisian data prioritas Rumus: (Jumlah data prioritas yang tersedia di Satu Data dibagi Potensi data prioritas) * 100% | I40: 0-100 | J40: 100 | K40: =J40 -> 100 | L40: List data prioritas dari masing-masing Perangkat Daerah (dari Bappeda) | M40: Dinas Komunikasi & Informatika
E41: d) | F41: Persentase Data yang Dirilis sesuai Jadwal (Aktualisasi & Ketepatan Waktu) | H41: Persentase data prioritas yang terupdate sesuai waktu A = 100% terupdate B = 75% terupdate C = 50% terupdate D = 25% terupdate E = belum terupdate (0%) | I41: A/B/C/D/E | J41: A | K41: =IF(J41="E",0,IF(J41="D",25,IF(J41="C",50, IF(J41="B",75,100)))) -> 100 | L41: Dokumen jumlah data prioritas yang telah terupdate (per 31 Desember n-1/tahun sebelumnya) pada 30 Juni tahun berjalan | M41: Dinas Komunikasi & Informatika
